Workbook
Name Base_Material: Materiais!$A$3:$E$1048576
Name Cadastro_de_Composição: #REF!

Sheet Materiais
A1: *BASE DOS CUSTOS: JULHO 2026
A2: Código | B2: Descrição | C2: UN | D2: GRUPO | E2: PROCEDENCIA
A3: 00035-013150 | B3: EXPANSAO PARA DCP RS232, RS 485 SDI12 | C3: UN | D3: AUTOMAÇÃO | E3: IMPORTADO | G3: =A3 -> 00035-013150
A4: 00045-001620 | B4: CONTROLADOR PARA ANTI-GEADA FROSTIE | C4: UN | D4: AUTOMAÇÃO | E4: IMPORTADO | G4: =A4 -> 00045-001620
A5: 01500-000001 | B5: TUBO IRRIGA PVC 350 DEFOFO JEI PN160-6M | C5: UN | D5: PVC TUBO | E5: PVC TUBO - NACIONAL | G5: =A5 -> 01500-000001
A6: 01500-000002 | B6: TUBO IRRIGA PVC 400 DEFOFO JEI PN160-6M | C6: UN | D6: PVC TUBO | E6: PVC TUBO - NACIONAL | G6: =A6 -> 01500-000002
A7: 01500-000003 | B7: TUBO IRRIGA PVC 600 DEFOFO JEI PN60-6M | C7: UN | D7: PVC TUBO | E7: PVC TUBO - NACIONAL | G7: =A7 -> 01500-000003
A8: 01500-000004 | B8: TUBO IRRIGA PVC 600 DEFOFO JEI PN80-6M | C8: UN | D8: PVC TUBO | E8: PVC TUBO - NACIONAL | G8: =A8 -> 01500-000004
A9: 01500-000005 | B9: TUBO IRRIGA PVC 600 DEFOFO JEI PN125-6M | C9: UN | D9: PVC TUBO | E9: PVC TUBO - NACIONAL | G9: =A9 -> 01500-000005
A10: 01500-000007 | B10: TUBO IRRIGA PVC 40 PB CL15 MARROM-6M | C10: UN | D10: PVC TUBO | E10: PVC TUBO - NACIONAL | G10: =A10 -> 01500-000007
A11: 01500-000008 | B11: TUBO AGBIAX PVC 250 DEFOFO JEI PN180-6M | C11: UN | D11: PVC TUBO | E11: PVC TUBO - NACIONAL | G11: =A11 -> 01500-000008
A12: 01500-000009 | B12: TUBO AGBIAX PVC 300 DEFOFO JEI PN180-6M | C12: UN | D12: PVC TUBO | E12: PVC TUBO - NACIONAL | G12: =A12 -> 01500-000009
A13: 01500-000010 | B13: TUBO AGBIAX PVC 300 DEFOFO JEI PN145-6M | C13: UN | D13: PVC TUBO | E13: PVC TUBO - NACIONAL | G13: =A13 -> 01500-000010
A14: 01500-000011 | B14: TUBO AGBIAX PVC 150 DEFOFO JEI PN145-6M | C14: UN | D14: PVC TUBO | E14: PVC TUBO - NACIONAL | G14: =A14 -> 01500-000011
... A4316: 71200-009800 | B4316: GALCON AC24 MODELO 800248 COM GABINETE | C4316: UN | D4316: AUTOMAÇÃO | E4316: IMPORTADO | G4316: =A4316 -> 71200-009800
A4317: 71200-009900 | B4317: GALCON MODULO 4 SAIDAS ADICIONAIS | C4317: UN | D4317: AUTOMAÇÃO | E4317: IMPORTADO
A4318: 71600-000147 | B4318: DOROT VALV MET 77-8" PN16 RE | C4318: UN | D4318: VÁLVULAS | E4318: IMPORTADO
A4319: 71600-000157 | B4319: DOROT VALV MET 77-6" PN16 RE | C4319: UN | D4319: VÁLVULAS | E4319: IMPORTADO
A4320: 71600-000158 | B4320: DOROT VALV MET 77-12" PN16 RE | C4320: UN | D4320: VÁLVULAS | E4320: IMPORTADO
A4321: 71600-000241 | B4321: DOROT VAL MET ALIVIO 84-3" BSP - 68215 | C4321: UN | D4321: VÁLVULAS | E4321: IMPORTADO
A4322: 71600-000257 | B4322: DOROT VALV MET 67-12" PR\PS(3w) -ISO25 | C4322: UN | D4322: VÁLVULAS | E4322: IMPORTADO
A4323: 71600-000266 | B4323: BF S52 PL A 2*2 BASIC BSP/VIC PN10 | C4323: UN | D4323: VÁLVULAS | E4323: IMPORTADO
A4324: 71600-000365 | B4324: DOROT V.ALIVIO A.PL S80 2"29-500Y-BSP | C4324: UN | D4324: VÁLVULAS | E4324: IMPORTADO
A4325: 71600-000374 | B4325: DOROT V.ALIVIO A.PL S80 1,5"29-500Y-BSP | C4325: UN | D4325: VÁLVULAS | E4325: IMPORTADO
A4326: 71600-001025 | B4326: TE SELETOR PRESSAO 8 X 1/8"X 8 | C4326: UN | D4326: VÁLVULAS | E4326: IMPORTADO
A4327: 71600-001265 | B4327: DOROT VALV PLAS 75T-1" BASICA - BSP | C4327: UN | D4327: VÁLVULAS | E4327: IMPORTADO
A4328: 71600-001280 | B4328: DOROT VALV PLAS 75-1" BASICA-BSP | C4328: UN | D4328: VÁLVULAS | E4328: IMPORTADO
... A5159: 78700-002500 | B5159: AREIA FILTRO ARESTADA N1 BASALTO - 25KG | C5159: UN | D5159: FILTROS | E5159: IMPORTADO

Sheet Orçamento
B1: ORÇAMENTO CANAL
B3: NOME CLIENTE: | F3: Espaço | G3: Área (HA) | I3: INFORMAÇÕES DO PROJETISTA:
B4: NOME DA FAZENDA: | F4: P01 | I4: NOME:
B5: CULTURA: | F5: P02 | I5: TELEFONE:
B6: CANAL: | F6: P03 | I6: E-MAIL:
B7: CIDADE: | F7: P04
B8: ESTADO: | F8: P05
B9: DATA: | F9: P06
B10: RTV NETAFIM: | F10: P07
B11: ÁREA TOTAL (HA) | D11: =G11 -> 0 | E11: SIM | F11: TOTAL | G11: =SUM(G3:G10) -> 0
B13: Área | C13: Cód. SAP | D13: Descricao | E13: Qtd | F13: Grupo | G13: Procedencia
B14: P01 | D14: =IFERROR(VLOOKUP(C14,Materiais!A:D,2,0),"") | F14: =IFERROR(VLOOKUP(C14,Materiais!A:E,4,0),"") | G14: =IFERROR(VLOOKUP(C14,Materiais!A:E,5,0),"")
B15: P01 | D15: =IFERROR(VLOOKUP(C15,Materiais!A:D,2,0),"") | F15: =IFERROR(VLOOKUP(C15,Materiais!A:E,4,0),"") | G15: =IFERROR(VLOOKUP(C15,Materiais!A:E,5,0),"")
B16: P01 | D16: =IFERROR(VLOOKUP(C16,Materiais!A:D,2,0),"") | F16: =IFERROR(VLOOKUP(C16,Materiais!A:E,4,0),"") | G16: =IFERROR(VLOOKUP(C16,Materiais!A:E,5,0),"")
B17: P01 | D17: =IFERROR(VLOOKUP(C17,Materiais!A:D,2,0),"") | F17: =IFERROR(VLOOKUP(C17,Materiais!A:E,4,0),"") | G17: =IFERROR(VLOOKUP(C17,Materiais!A:E,5,0),"")
B18: P01 | F18: =IFERROR(VLOOKUP(C18,Materiais!A:E,4,0),"") | G18: =IFERROR(VLOOKUP(C18,Materiais!A:E,5,0),"")
B19: P01 | D19: =IFERROR(VLOOKUP(C19,Materiais!A:D,2,0),"") | F19: =IFERROR(VLOOKUP(C19,Materiais!A:E,4,0),"") | G19: =IFERROR(VLOOKUP(C19,Materiais!A:E,5,0),"")
B20: P01 | D20: =IFERROR(VLOOKUP(C20,Materiais!A:D,2,0),"") | F20: =IFERROR(VLOOKUP(C20,Materiais!A:E,4,0),"") | G20: =IFERROR(VLOOKUP(C20,Materiais!A:E,5,0),"")
B21: P01 | D21: =IFERROR(VLOOKUP(C21,Materiais!A:D,2,0),"") | F21: =IFERROR(VLOOKUP(C21,Materiais!A:E,4,0),"") | G21: =IFERROR(VLOOKUP(C21,Materiais!A:E,5,0),"")
B22: P01 | D22: =IFERROR(VLOOKUP(C22,Materiais!A:D,2,0),"") | F22: =IFERROR(VLOOKUP(C22,Materiais!A:E,4,0),"") | G22: =IFERROR(VLOOKUP(C22,Materiais!A:E,5,0),"")
B23: P01 | D23: =IFERROR(VLOOKUP(C23,Materiais!A:D,2,0),"") | F23: =IFERROR(VLOOKUP(C23,Materiais!A:E,4,0),"") | G23: =IFERROR(VLOOKUP(C23,Materiais!A:E,5,0),"")
B24: P01 | D24: =IFERROR(VLOOKUP(C24,Materiais!A:D,2,0),"") | F24: =IFERROR(VLOOKUP(C24,Materiais!A:E,4,0),"") | G24: =IFERROR(VLOOKUP(C24,Materiais!A:E,5,0),"")
B25: P01 | D25: =IFERROR(VLOOKUP(C25,Materiais!A:D,2,0),"") | F25: =IFERROR(VLOOKUP(C25,Materiais!A:E,4,0),"") | G25: =IFERROR(VLOOKUP(C25,Materiais!A:E,5,0),"")
B26: P01 | D26: =IFERROR(VLOOKUP(C26,Materiais!A:D,2,0),"") | F26: =IFERROR(VLOOKUP(C26,Materiais!A:E,4,0),"") | G26: =IFERROR(VLOOKUP(C26,Materiais!A:E,5,0),"")
B27: P01 | D27: =IFERROR(VLOOKUP(C27,Materiais!A:D,2,0),"") | F27: =IFERROR(VLOOKUP(C27,Materiais!A:E,4,0),"") | G27: =IFERROR(VLOOKUP(C27,Materiais!A:E,5,0),"")
B28: P01 | D28: =IFERROR(VLOOKUP(C28,Materiais!A:D,2,0),"") | F28: =IFERROR(VLOOKUP(C28,Materiais!A:E,4,0),"") | G28: =IFERROR(VLOOKUP(C28,Materiais!A:E,5,0),"")
B29: P01 | D29: =IFERROR(VLOOKUP(C29,Materiais!A:D,2,0),"") | F29: =IFERROR(VLOOKUP(C29,Materiais!A:E,4,0),"") | G29: =IFERROR(VLOOKUP(C29,Materiais!A:E,5,0),"")
B30: P01 | D30: =IFERROR(VLOOKUP(C30,Materiais!A:D,2,0),"") | F30: =IFERROR(VLOOKUP(C30,Materiais!A:E,4,0),"") | G30: =IFERROR(VLOOKUP(C30,Materiais!A:E,5,0),"")
... B153: P01 | D153: =IFERROR(VLOOKUP(C153,Materiais!A:D,2,0),"") | F153: =IFERROR(VLOOKUP(C153,Materiais!A:E,4,0),"") | G153: =IFERROR(VLOOKUP(C153,Materiais!A:E,5,0),"")
B154: P02 | D154: P02
B155: P02 | F155: =IFERROR(VLOOKUP(C155,Materiais!A:E,4,0),"") | G155: =IFERROR(VLOOKUP(C155,Materiais!A:E,5,0),"")
B156: P02 | F156: =IFERROR(VLOOKUP(C156,Materiais!A:E,4,0),"") | G156: =IFERROR(VLOOKUP(C156,Materiais!A:E,5,0),"")
B157: P02 | F157: =IFERROR(VLOOKUP(C157,Materiais!A:E,4,0),"") | G157: =IFERROR(VLOOKUP(C157,Materiais!A:E,5,0),"")
B158: P02 | F158: =IFERROR(VLOOKUP(C158,Materiais!A:E,4,0),"") | G158: =IFERROR(VLOOKUP(C158,Materiais!A:E,5,0),"")
B159: P02 | F159: =IFERROR(VLOOKUP(C159,Materiais!A:E,4,0),"") | G159: =IFERROR(VLOOKUP(C159,Materiais!A:E,5,0),"")
B160: P02 | F160: =IFERROR(VLOOKUP(C160,Materiais!A:E,4,0),"") | G160: =IFERROR(VLOOKUP(C160,Materiais!A:E,5,0),"")
B161: P02 | F161: =IFERROR(VLOOKUP(C161,Materiais!A:E,4,0),"") | G161: =IFERROR(VLOOKUP(C161,Materiais!A:E,5,0),"")
B162: P02 | F162: =IFERROR(VLOOKUP(C162,Materiais!A:E,4,0),"") | G162: =IFERROR(VLOOKUP(C162,Materiais!A:E,5,0),"")
B163: P02 | F163: =IFERROR(VLOOKUP(C163,Materiais!A:E,4,0),"") | G163: =IFERROR(VLOOKUP(C163,Materiais!A:E,5,0),"")
B164: P02 | F164: =IFERROR(VLOOKUP(C164,Materiais!A:E,4,0),"") | G164: =IFERROR(VLOOKUP(C164,Materiais!A:E,5,0),"")
...

Sheet Premissas
A1: ESTADO: | B1: CONDIÇÃO DE PAGTO: | C1: COMISSÃO CANAL:
A2: AC | B2: FINAME | C2: SIM
A3: AL | B3: RECURSO PRÓPRIO | C3: NÃO
A4: AM | B4: DLL
A5: AP
A6: BA
A7: CE
A8: DF
A9: ES
A10: GO
A11: MA
A12: MG
A13: MS
A14: MT
A15: PA
A16: PB
... A28: TO
